<?xml version="1.0" ?>

<robot name="myRobot" xmlns:xacro="http://www.ros.org/wiki/xacro">
  <!-- MODELS -->
  <material name="myRobot/Green">
    <color rgba="0.0 1.0 0.0 1.0"/>
  </material>
  <material name="myRobot/Yellow">
    <color rgba="1.0 1.0 0.0 1.0"/>
  </material>
  <material name="myRobot/LightYellow">
    <color rgba="1.0 1.0 0.6 1.0"/>
  </material>
  <material name="myRobot/Blue">
    <color rgba="0.0 0.0 1.0 1.0"/>
  </material>
  <material name="myRobot/LightBlue">
    <color rgba="0.6 0.79 1.0 1.0"/>
  </material>
  <material name="myRobot/DarkGrey">
    <color rgba="0.31 0.31 0.31 1.0"/>
  </material>
  <material name="myRobot/LightGrey">
    <color rgba="0.83 0.83 0.83 1.0"/>
  </material>
  <material name="myRobot/MediumGrey">
    <color rgba="0.5 0.5 0.5 1.0"/>
  </material>
  <material name="myRobot/Black">
    <color rgba="0.0 0.0 0.0 1.0"/>
  </material>
  <material name="myRobot/Red">
    <color rgba="1.0 0.0 0.0 1.0"/>
  </material>
  <material name="myRobot/Orange">
    <color rgba="1.0 0.65 0.0 1.0"/>
  </material>
  <!-- sec add start -->
  <!-- sec add end -->
  <link name="base_link">
    <inertial>
      <origin rpy="0 0 0" xyz="0 0 0"/>
      <mass value="0"/>
      <inertia ixx="0.0" ixy="0.0" ixz="0.0" iyy="0.0" iyz="0.0" izz="0.0"/>
    </inertial>
    <!-- sec add end -->
  </link>
  <joint name="base_joint" type="fixed">
    <origin rpy="0 0 0" xyz="0 0 0"/>
    <parent link="base_link"/>
    <child link="chassis"/>
  </joint>
  <link name="chassis">
    <inertial>
      <origin rpy="0 0 0" xyz="0 0 -0.1"/>
      <mass value="10"/>
      <inertia ixx="0.425" ixy="0.0" ixz="0.0" iyy="0.425" iyz="0.0" izz="0.85"/>
    </inertial>
    <visual>
      <origin rpy="0 0 0" xyz="0 0 0"/>
      <geometry>
        <!-- sec mod start -->
        <mesh filename="/home/liu/.gazebo/models/create/meshes/create_body.dae" scale="1.0 1.0 1.0"/>
        <!--                <cylinder length="0.08" radius="0.17"/> -->
        <!-- sec mod end -->
      </geometry>
      <material name="MyRobot/LightGrey"/>
    </visual>
    <collision>
      <origin rpy="0 0 0" xyz="0 0 0"/>
      <geometry>
        <!-- sec mod start -->
        <mesh filename="/home/liu/.gazebo/models/create/meshes/create_body.dae" scale="1.0 1.0 1.0"/>
        <!--<cylinder length="0.08" radius="0.17"/>-->
        <!-- sec mod end -->
      </geometry>
    </collision>
  </link>
  <!-- sec add start -->
  <gazebo reference="chassis">
    <sensor name="chassis_sensor" type="contact">
      <always_on>true</always_on>
      <update_rate>1.0</update_rate>
      <contact>
        <collision>chassis_collision</collision>
      </contact>
    </sensor>
  </gazebo>
  <!-- sec add end -->
  <joint name="left_axis_base_joint" type="fixed">
    <origin rpy="0 0 0" xyz="0.0 0.14 -0.02"/>
    <parent link="chassis"/>
    <child link="left_axis"/>
  </joint>
  <link name="left_axis">
    <inertial>
      <origin rpy="-1.57079632679 0 0" xyz="0 0 0"/>
      <mass value="0.001"/>
      <inertia ixx="6.25e-07" ixy="0.0" ixz="0.0" iyy="6.25e-07" iyz="0.0" izz="2.08333333333e-07"/>
    </inertial>
    <visual>
      <origin rpy="-1.57079632679 0 0" xyz="0 0 0"/>
      <geometry>
        <cylinder length="0.02" radius="0.0025"/>
      </geometry>
      <material name="myRobot/MediumGray"/>
    </visual>
    <collision>
      <origin rpy="-1.57079632679 0 0" xyz="0 0 0"/>
      <geometry>
        <cylinder length="0.02" radius="0.0025"/>
      </geometry>
    </collision>
  </link>
  <gazebo reference="left_axis_axis">
    <gravity>true</gravity>
    <material>Gazebo/Red</material>
    <mu1>0.8</mu1>
    <mu2>0.8</mu2>
  </gazebo>
  <joint name="left_wheel_rot_joint" type="continuous">
    <origin rpy="0 0 0" xyz="0 0 0"/>
    <axis xyz="0 1 0"/>
    <limit effort="100" velocity="100"/>
    <joint_properties damping="0.0" friction="0.0"/>
    <parent link="left_axis"/>
    <child link="left_wheel_link"/>
  </joint>
  <link name="left_wheel_link">
    <inertial>
      <origin rpy="-1.57079632679 0 0" xyz="0 0.01 0"/>
      <mass value="0.5"/>
      <inertia ixx="0.00375" ixy="0.0" ixz="0.0" iyy="0.00375" iyz="0.0" izz="0.00125"/>
    </inertial>
    <visual>
      <origin rpy="-1.57079632679 0 0" xyz="0 0 0"/>
      <geometry>
        <cylinder length="0.02" radius="0.03"/>
      </geometry>
      <material name="myRobot/Black"/>
    </visual>
    <collision>
      <origin rpy="-1.57079632679 0 0" xyz="0 0 0"/>
      <geometry>
        <cylinder length="0.02" radius="0.03"/>
      </geometry>
    </collision>
  </link>
  <gazebo reference="left_wheel_link">
    <gravity>true</gravity>
    <material>Gazebo/Grey</material>
    <mu1>50</mu1>
    <mu2>10</mu2>
    <kp>10000000</kp>
    <kd>1</kd>
    <fdir1>1 0 0</fdir1>
    <minDepth>0.0001</minDepth>
    <maxContacts>1</maxContacts>
  </gazebo>
  <joint name="right_axis_base_joint" type="fixed">
    <origin rpy="0 0 0" xyz="0.0 -0.14 -0.02"/>
    <parent link="chassis"/>
    <child link="right_axis"/>
  </joint>
  <link name="right_axis">
    <inertial>
      <origin rpy="-1.57079632679 0 0" xyz="0 0 0"/>
      <mass value="0.001"/>
      <inertia ixx="6.25e-07" ixy="0.0" ixz="0.0" iyy="6.25e-07" iyz="0.0" izz="2.08333333333e-07"/>
    </inertial>
    <visual>
      <origin rpy="-1.57079632679 0 0" xyz="0 0 0"/>
      <geometry>
        <cylinder length="0.02" radius="0.0025"/>
      </geometry>
      <material name="myRobot/MediumGray"/>
    </visual>
    <collision>
      <origin rpy="-1.57079632679 0 0" xyz="0 0 0"/>
      <geometry>
        <cylinder length="0.02" radius="0.0025"/>
      </geometry>
    </collision>
  </link>
  <gazebo reference="right_axis_axis">
    <gravity>true</gravity>
    <material>Gazebo/Red</material>
    <mu1>0.8</mu1>
    <mu2>0.8</mu2>
  </gazebo>
  <joint name="right_wheel_rot_joint" type="continuous">
    <origin rpy="0 0 0" xyz="0 0 0"/>
    <axis xyz="0 1 0"/>
    <limit effort="100" velocity="100"/>
    <joint_properties damping="0.0" friction="0.0"/>
    <parent link="right_axis"/>
    <child link="right_wheel_link"/>
  </joint>
  <link name="right_wheel_link">
    <inertial>
      <origin rpy="-1.57079632679 0 0" xyz="0 0.01 0"/>
      <mass value="0.5"/>
      <inertia ixx="0.00375" ixy="0.0" ixz="0.0" iyy="0.00375" iyz="0.0" izz="0.00125"/>
    </inertial>
    <visual>
      <origin rpy="-1.57079632679 0 0" xyz="0 0 0"/>
      <geometry>
        <cylinder length="0.02" radius="0.03"/>
      </geometry>
      <material name="myRobot/Black"/>
    </visual>
    <collision>
      <origin rpy="-1.57079632679 0 0" xyz="0 0 0"/>
      <geometry>
        <cylinder length="0.02" radius="0.03"/>
      </geometry>
    </collision>
  </link>
  <gazebo reference="right_wheel_link">
    <gravity>true</gravity>
    <material>Gazebo/Grey</material>
    <mu1>50</mu1>
    <mu2>10</mu2>
    <kp>10000000</kp>
    <kd>1</kd>
    <fdir1>1 0 0</fdir1>
    <minDepth>0.0001</minDepth>
    <maxContacts>1</maxContacts>
  </gazebo>

  <joint name="sphere_joint2" type="continuous">
    <origin rpy="0 0 0" xyz="-0.10 0 -0.03"/>
    <axis xyz="0 1 0"/>
    <limit effort="100" velocity="100"/>
    <joint_properties damping="0.0" friction="0.0"/>
    <parent link="chassis"/>
    <child link="sphere2"/>
  </joint>
  <link name="sphere2">
    <inertial>
       <origin rpy="-1.57079632679 0 0" xyz="0 0.01 0"/>
      <mass value="0.3"/>
      <inertia ixx="0.00375" ixy="0.0" ixz="0.0" iyy="0.00375" iyz="0.0" izz="0.00125"/>
    </inertial>
    <visual>
      <origin rpy="-1.57079632679 0 0" xyz="0 0 0"/>
      <geometry>
        <cylinder length="0.007" radius="0.02"/>
      </geometry>
      <material name="myRobot/Black"/>
    </visual>
    <collision>
      <origin rpy="-1.57079632679 0 0" xyz="0 0 0"/>
      <geometry>
        <cylinder length="0.007" radius="0.02"/>
      </geometry>
    </collision>
  </link>

  <!-- Laser link and plugin -->
  
  <joint name="hokuyo_laser_joint" type="fixed">
    <axis xyz="0 0 1"/>
    <origin rpy="0 0 0" xyz="0.20 0 0.1"/>
    <parent link="base_link"/>
    <child link="hokuyo_laser_link"/>
  </joint>
  <link name="hokuyo_laser_link">
    <collision>
      <origin rpy="0 0 0" xyz="0 0 0"/>
      <geometry>
        <cylinder length="0.047" radius="0.025"/>
      </geometry>
    </collision>
    <visual>
      <origin rpy="0 0 0" xyz="-0.275 0 -0.07"/>
      <geometry>
        <cylinder length="0.047" radius="0.025"/>
      </geometry>
      <material name="myRobot/LightBlue"/>
    </visual>
    <inertial>
      <mass value="1e-5"/>
      <origin rpy="0 0 0" xyz="0 0 0"/>
      <inertia ixx="1e-6" ixy="0" ixz="0" iyy="1e-6" iyz="0" izz="1e-6"/>
    </inertial>
  </link>
  <gazebo reference="hokuyo_laser_link">
    <gravity>true</gravity>
    <sensor name="head_hokuyo_sensor" type="ray">
      <pose>0 0 0 0 0 0</pose>
      <visualize>true</visualize>
      <update_rate>40</update_rate>
      <ray>
        <scan>
          <horizontal>
            <samples>360</samples>
            <resolution>1</resolution>
            <min_angle>-2.356195</min_angle>
            <max_angle>2.356195</max_angle>
          </horizontal>
        </scan>
        <range>
          <min>0.2</min>
          <max>4</max>
          <resolution>0.125</resolution>
        </range>
        <noise>
          <type>gaussian</type>
          <mean>0.0</mean>
          <stddev>0.0</stddev>
        </noise>
      </ray>
      
      <plugin filename="libgazebo_ros_laser.so" name="gazebo_ros_head_hokuyo_controller">
        <rosDebugLevel>WARN</rosDebugLevel>
        <robotNamespace>/myRobot/</robotNamespace>
        <topicName>laser_scan</topicName>
        <frameName>hokuyo_laser_link</frameName>
        <noiseMean>0.0</noiseMean>
        <noiseStddev>0.0</noiseStddev>
      </plugin>
  
    </sensor>
  </gazebo>
  
  <!--Camera link and plugin-->
  
  <joint name="camera_sensor_right_joint" type="fixed">
    <axis xyz="1 0 0"/>
    <origin rpy="0 -1.5708 0" xyz="0.175 -0.05 0.005"/>
    <parent link="base_link"/>
    <child link="camera_sensor_right_link"/>
  </joint>
  <link name="camera_sensor_right_link">
    <collision>
      <origin rpy="0 0 0" xyz="0 0 0"/>
      <geometry>
        <cylinder length="0.02" radius="0.0025"/>
      </geometry>
    </collision>
    <visual>
      <origin rpy="0 1.57 0" xyz="0 0 0"/>
      <geometry>
        <cylinder length="0.02" radius="0.0025"/>
      </geometry>
      <material name="myRobot/Green"/>
    </visual>
    <inertial>
      <mass value="0.0001"/>
      <origin rpy="0 0 3.14159265359" xyz="0 0 0"/>
      <inertia ixx="0.0000001" ixy="0" ixz="0" iyy="0.0000001" iyz="0" izz="0.0000001"/>
    </inertial>
  </link>
  <gazebo reference="camera_sensor_right_link">
    <sensor name="camera_sensor_right" type="camera">
      <update_rate>10</update_rate>
      <camera name="head">
        <horizontal_fov>1.5708</horizontal_fov>
        <image>
          <width>640</width>
          <height>480</height>
          <format>R8G8B8</format>
        </image>
        <clip>
          <near>0.02</near>
          <far>300</far>
        </clip>
        <noise>
          <type>gaussian</type>
          <mean>0.0</mean>
          <stddev>0.007</stddev>
        </noise>
      </camera>
      <plugin filename="libgazebo_ros_camera.so" name="camera_sensor_right_controller">
        <alwaysOn>true</alwaysOn>
        <updateRate>0.0</updateRate>
        <cameraName>stereo/right</cameraName>
        <imageTopicName>image_raw</imageTopicName>
        <cameraInfoTopicName>camera_info</cameraInfoTopicName>
        <frameName>camera_sensor_right_link</frameName>
        <hackBaseline>0.07</hackBaseline>
        <distortionK1>0.0</distortionK1>
        <distortionK2>0.0</distortionK2>
        <distortionK3>0.0</distortionK3>
        <distortionT1>0.0</distortionT1>
        <distortionT2>0.0</distortionT2>
        <blurSigma>0</blurSigma>
        <distortionSigma>0.0</distortionSigma>
      </plugin>
    </sensor>
  </gazebo>
  <joint name="camera_sensor_left_joint" type="fixed">
    <axis xyz="1 0 0"/>
    <origin rpy="0 -1.5708 0" xyz="0.175 0.05 0.005"/>
    <parent link="base_link"/>
    <child link="camera_sensor_left_link"/>
  </joint>
  <link name="camera_sensor_left_link">
    <collision>
      <origin rpy="0 0 0" xyz="0 0 0"/>
      <geometry>
        <cylinder length="0.02" radius="0.0025"/>
      </geometry>
    </collision>
    <visual>
      <origin rpy="0 1.57 0" xyz="0 0 0"/>
      <geometry>
        <cylinder length="0.02" radius="0.0025"/>
      </geometry>
      <material name="myRobot/Green"/>
    </visual>
    <inertial>
      <mass value="0.0001"/>
      <origin rpy="0 0 3.14159265359" xyz="0 0 0"/>
      <inertia ixx="0.0000001" ixy="0" ixz="0" iyy="0.0000001" iyz="0" izz="0.0000001"/>
    </inertial>
  </link>
  <gazebo reference="camera_sensor_left_link">
    <sensor name="camera_sensor_left" type="camera">
      <update_rate>10</update_rate>
      <camera name="head">
        <horizontal_fov>1.5708</horizontal_fov>
        <image>
          <width>640</width>
          <height>480</height>
          <format>R8G8B8</format>
        </image>
        <clip>
          <near>0.02</near>
          <far>300</far>
        </clip>
        <noise>
          <type>gaussian</type>
          <mean>0.0</mean>
          <stddev>0.00</stddev>
        </noise>
      </camera>
      <plugin filename="libgazebo_ros_camera.so" name="camera_sensor_left_controller">
        <rosDebugLevel>WARN</rosDebugLevel>
        <alwaysOn>true</alwaysOn>
        <updateRate>0.0</updateRate>
        <cameraName>stereo/left</cameraName>
        <imageTopicName>image_raw</imageTopicName>
        <cameraInfoTopicName>camera_info</cameraInfoTopicName>
        <frameName>camera_sensor_left_link</frameName>
        <hackBaseline>0.07</hackBaseline>
        <distortionK1>0.0</distortionK1>
        <distortionK2>0.0</distortionK2>
        <distortionK3>0.0</distortionK3>
        <distortionT1>0.0</distortionT1>
        <distortionT2>0.0</distortionT2>
        <blurSigma>0.0</blurSigma>
        <distortionSigma>0</distortionSigma>
      </plugin>
    </sensor>
  </gazebo>

  <joint name="optical_ranging_sensor_left_joint" type="fixed">
    <axis xyz="0 0 1"/>
    <origin rpy="0 0 0.174532925199" xyz="0.12 0.2 0.05"/>
    <parent link="base_link"/>
    <child link="optical_ranging_sensor_left_link"/>
  </joint>
  <link name="optical_ranging_sensor_left_link">
    <collision>
      <origin rpy="0 0 0" xyz="0 0 0"/>
      <geometry>
        <box size="0.01 0.01 0.01"/>
      </geometry>
    </collision>
    <visual>
      <origin rpy="0 0 0" xyz="0 0 0"/>
      <geometry>
        <box size="0.01 0.01 0.01"/>
      </geometry>
      <material name="iRobot/Red"/>
    </visual>
    <inertial>
      <mass value="0.000000000000000001"/>
      <origin rpy="0 0 0" xyz="0 0 0"/>
      <inertia ixx="0.00000015" ixy="0" ixz="0" iyy="0.00000015" iyz="0" izz="0.00000015"/>
    </inertial>
  </link>
  <gazebo reference="optical_ranging_sensor_left_link">
    <sensor name="optical_ranging_sensor_left_sensor" type="ray">
      <update_rate>1</update_rate>
      <visualize>false</visualize>
      <ray>
        <range>
          <min>0.02</min>
          <max>0.2</max>
          <resolution>1</resolution>
        </range>
        <scan>
          <horizontal>
            <samples>3</samples>
            <min_angle>-0.01</min_angle>
            <max_angle>0.01</max_angle>
          </horizontal>

        </scan>
      </ray>
    </sensor>
  </gazebo>
  <joint name="optical_ranging_sensor_right_joint" type="fixed">
    <axis xyz="0 0 1"/>
    <origin rpy="0 0 -0.174532925199" xyz="0.12 -0.2 0.05"/>
    <parent link="base_link"/>
    <child link="optical_ranging_sensor_right_link"/>
  </joint>
  <link name="optical_ranging_sensor_right_link">
    <collision>
      <origin rpy="0 0 0" xyz="0 0 0"/>
      <geometry>
        <box size="0.01 0.01 0.01"/>
      </geometry>
    </collision>
    <visual>
      <origin rpy="0 0 0" xyz="0 0 0"/>
      <geometry>
        <box size="0.01 0.01 0.01"/>
      </geometry>
      <material name="iRobot/Red"/>
    </visual>
    <inertial>
      <mass value="0.000000000000000001"/>
      <origin rpy="0 0 0" xyz="0 0 0"/>
      <inertia ixx="0.00000015" ixy="0" ixz="0" iyy="0.00000015" iyz="0" izz="0.00000015"/>
    </inertial>
  </link>
  <gazebo reference="optical_ranging_sensor_right_link">
    <sensor name="optical_ranging_sensor_right_sensor" type="ray">
      <update_rate>1</update_rate>
      <visualize>false</visualize>
      <ray>
        <range>
          <min>0.02</min>
          <max>0.2</max>
          <resolution>1</resolution>
        </range>
        <scan>
          <horizontal>
            <samples>3</samples>
            <min_angle>-0.01</min_angle>
            <max_angle>0.01</max_angle>
          </horizontal>
          <!--
                <vertical>
                  <samples>3</samples>
                  <min_angle>-0.0436</min_angle>
                  <max_angle>0.0436</max_angle>
                </vertical>
-->
        </scan>
      </ray>
    </sensor>
  </gazebo>
  <joint name="ultrasonic_sensor_left_joint" type="fixed">
    <axis xyz="0 0 1"/>
    <origin rpy="0 0 0.174532925199" xyz="0.12 0.2 0.05"/>
    <parent link="base_link"/>
    <child link="ultrasonic_sensor_left_link"/>
  </joint>
  <link name="ultrasonic_sensor_left_link">
    <collision>
      <origin rpy="0 0 0" xyz="0 0 0"/>
      <geometry>
        <box size="0.01 0.01 0.01"/>
      </geometry>
    </collision>
    <visual>
      <origin rpy="0 0 0" xyz="0 0 0"/>
      <geometry>
        <box size="0.01 0.01 0.01"/>
      </geometry>
      <material name="iRobot/Red"/>
    </visual>
    <inertial>
      <mass value="0.000000000000000001"/>
      <origin rpy="0 0 0" xyz="0 0 0"/>
      <inertia ixx="0.00000015" ixy="0" ixz="0" iyy="0.00000015" iyz="0" izz="0.00000015"/>
    </inertial>
  </link>
  <gazebo reference="ultrasonic_sensor_left_link">
    <sensor name="ultrasonic_sensor_left_sensor" type="ray">
      <update_rate>1</update_rate>
      <visualize>false</visualize>
      <ray>
        <range>
          <min>0.02</min>
          <max>0.5</max>
          <resolution>1</resolution>
        </range>
        <scan>
          <horizontal>
            <samples>3</samples>
            <min_angle>-0.01</min_angle>
            <max_angle>0.01</max_angle>
          </horizontal>

        </scan>
      </ray>
    </sensor>
  </gazebo>
  <joint name="ultrasonic_sensor_right_joint" type="fixed">
    <axis xyz="0 0 1"/>
    <origin rpy="0 0 -0.174532925199" xyz="0.12 -0.2 0.05"/>
    <parent link="base_link"/>
    <child link="ultrasonic_sensor_right_link"/>
  </joint>
  <link name="ultrasonic_sensor_right_link">
    <collision>
      <origin rpy="0 0 0" xyz="0 0 0"/>
      <geometry>
        <box size="0.01 0.01 0.01"/>
      </geometry>
    </collision>
    <visual>
      <origin rpy="0 0 0" xyz="0 0 0"/>
      <geometry>
        <box size="0.01 0.01 0.01"/>
      </geometry>
      <material name="iRobot/Red"/>
    </visual>
    <inertial>
      <mass value="0.000000000000000001"/>
      <origin rpy="0 0 0" xyz="0 0 0"/>
      <inertia ixx="0.00000015" ixy="0" ixz="0" iyy="0.00000015" iyz="0" izz="0.00000015"/>
    </inertial>
  </link>
  <gazebo reference="ultrasonic_sensor_right_link">
    <sensor name="ultrasonic_sensor_right_sensor" type="ray">
      <update_rate>1</update_rate>
      <visualize>false</visualize>
      <ray>
        <range>
          <min>0.02</min>
          <max>0.5</max>
          <resolution>1</resolution>
        </range>
        <scan>
          <horizontal>
            <samples>3</samples>
            <min_angle>-0.01</min_angle>
            <max_angle>0.01</max_angle>
          </horizontal>

        </scan>
      </ray>
    </sensor>
  </gazebo>
  <joint name="cliff_sensor_front_right_joint" type="fixed">
    <axis xyz="0 0 1"/>
    <origin rpy="0 1.57079632679 0" xyz="0.1 -0.15 0.0"/>
    <parent link="base_link"/>
    <child link="cliff_sensor_front_right_link"/>
  </joint>
  <link name="cliff_sensor_front_right_link">
    <collision>
      <origin rpy="0 0 0" xyz="0 0 0"/>
      <geometry>
        <box size="0.01 0.01 0.01"/>
      </geometry>
    </collision>
    <visual>
      <origin rpy="0 0 0" xyz="0 0 0"/>
      <geometry>
        <box size="0.01 0.01 0.01"/>
      </geometry>
      <material name="iRobot/Red"/>
    </visual>
    <inertial>
      <mass value="0.000000000000000001"/>
      <origin rpy="0 0 0" xyz="0 0 0"/>
      <inertia ixx="0.00000015" ixy="0" ixz="0" iyy="0.00000015" iyz="0" izz="0.00000015"/>
    </inertial>
  </link>
  <gazebo reference="cliff_sensor_front_right_link">
    <sensor name="cliff_sensor_front_right_sensor" type="ray">
      <update_rate>50</update_rate>
      <visualize>true</visualize>
      <ray>
        <range>
          <min>0.02</min>
          <max>0.2</max>
          <resolution>1</resolution>
        </range>
        <scan>
          <horizontal>
            <samples>3</samples>
            <min_angle>-0.01</min_angle>
            <max_angle>0.01</max_angle>
          </horizontal>

        </scan>
      </ray>
      <plugin filename="libgazebo_ros_cliff.so" name="cliff_sensor_front_right_plugin">
        <gaussianNoise>0.000</gaussianNoise>
        <threshold>0.06</threshold>
        <topicName>cliff</topicName>
        <frameName>cliff_sensor_front_right</frameName>
        <radiation>infrared</radiation>
        <fov>0</fov>
        <updateRate>0</updateRate>
        <robotNamespace>/myRobot</robotNamespace>
      </plugin>
    </sensor>
  </gazebo>
  <joint name="cliff_sensor_back_right_joint" type="fixed">
    <axis xyz="0 0 1"/>
    <origin rpy="0 1.57079632679 0" xyz="-0.05 -0.15 0.0"/>
    <parent link="base_link"/>
    <child link="cliff_sensor_back_right_link"/>
  </joint>
  <link name="cliff_sensor_back_right_link">
    <collision>
      <origin rpy="0 0 0" xyz="0 0 0"/>
      <geometry>
        <box size="0.01 0.01 0.01"/>
      </geometry>
    </collision>
    <visual>
      <origin rpy="0 0 0" xyz="0 0 0"/>
      <geometry>
        <box size="0.01 0.01 0.01"/>
      </geometry>
      <material name="iRobot/Red"/>
    </visual>
    <inertial>
      <mass value="0.000000000000000001"/>
      <origin rpy="0 0 0" xyz="0 0 0"/>
      <inertia ixx="0.00000015" ixy="0" ixz="0" iyy="0.00000015" iyz="0" izz="0.00000015"/>
    </inertial>
  </link>
  <gazebo reference="cliff_sensor_back_right_link">
    <sensor name="cliff_sensor_back_right_sensor" type="ray">
      <update_rate>50</update_rate>
      <visualize>true</visualize>
      <ray>
        <range>
          <min>0.02</min>
          <max>0.2</max>
          <resolution>1</resolution>
        </range>
        <scan>
          <horizontal>
            <samples>3</samples>
            <min_angle>-0.01</min_angle>
            <max_angle>0.01</max_angle>
          </horizontal>

        </scan>
      </ray>
      <plugin filename="libgazebo_ros_cliff.so" name="cliff_sensor_back_right_plugin">
        <gaussianNoise>0.000</gaussianNoise>
        <threshold>0.06</threshold>
        <topicName>cliff</topicName>
        <frameName>cliff_sensor_back_right</frameName>
        <radiation>infrared</radiation>
        <fov>0</fov>
        <updateRate>0</updateRate>
        <robotNamespace>/myRobot</robotNamespace>
      </plugin>
    </sensor>
  </gazebo>
  <joint name="cliff_sensor_front_left_joint" type="fixed">
    <axis xyz="0 0 1"/>
    <origin rpy="0 1.57079632679 0" xyz="0.1 0.15 0.0"/>
    <parent link="base_link"/>
    <child link="cliff_sensor_front_left_link"/>
  </joint>
  <link name="cliff_sensor_front_left_link">
    <collision>
      <origin rpy="0 0 0" xyz="0 0 0"/>
      <geometry>
        <box size="0.01 0.01 0.01"/>
      </geometry>
    </collision>
    <visual>
      <origin rpy="0 0 0" xyz="0 0 0"/>
      <geometry>
        <box size="0.01 0.01 0.01"/>
      </geometry>
      <material name="iRobot/Red"/>
    </visual>
    <inertial>
      <mass value="0.000000000000000001"/>
      <origin rpy="0 0 0" xyz="0 0 0"/>
      <inertia ixx="0.00000015" ixy="0" ixz="0" iyy="0.00000015" iyz="0" izz="0.00000015"/>
    </inertial>
  </link>
  <gazebo reference="cliff_sensor_front_left_link">
    <sensor name="cliff_sensor_front_left_sensor" type="ray">
      <update_rate>50</update_rate>
      <visualize>true</visualize>
      <ray>
        <range>
          <min>0.02</min>
          <max>0.2</max>
          <resolution>1</resolution>
        </range>
        <scan>
          <horizontal>
            <samples>3</samples>
            <min_angle>-0.01</min_angle>
            <max_angle>0.01</max_angle>
          </horizontal>
          <!--
                <vertical>
                  <samples>3</samples>
                  <min_angle>-0.0436</min_angle>
                  <max_angle>0.0436</max_angle>
                </vertical>
-->
        </scan>
      </ray>
      <plugin filename="libgazebo_ros_cliff.so" name="cliff_sensor_front_left_plugin">
        <gaussianNoise>0.000</gaussianNoise>
        <threshold>0.06</threshold>
        <topicName>cliff</topicName>
        <frameName>cliff_sensor_front_left</frameName>
        <radiation>infrared</radiation>
        <fov>0</fov>
        <updateRate>0</updateRate>
        <robotNamespace>/myRobot</robotNamespace>
      </plugin>
    </sensor>
  </gazebo>
  <joint name="cliff_sensor_back_left_joint" type="fixed">
    <axis xyz="0 0 1"/>
    <origin rpy="0 1.57079632679 0" xyz="-0.05 0.15 0.0"/>
    <parent link="base_link"/>
    <child link="cliff_sensor_back_left_link"/>
  </joint>
  <link name="cliff_sensor_back_left_link">
    <collision>
      <origin rpy="0 0 0" xyz="0 0 0"/>
      <geometry>
        <box size="0.01 0.01 0.01"/>
      </geometry>
    </collision>
    <visual>
      <origin rpy="0 0 0" xyz="0 0 0"/>
      <geometry>
        <box size="0.01 0.01 0.01"/>
      </geometry>
      <material name="iRobot/Red"/>
    </visual>
    <inertial>
      <mass value="0.000000000000000001"/>
      <origin rpy="0 0 0" xyz="0 0 0"/>
      <inertia ixx="0.00000015" ixy="0" ixz="0" iyy="0.00000015" iyz="0" izz="0.00000015"/>
    </inertial>
  </link>
  <gazebo reference="cliff_sensor_back_left_link">
    <sensor name="cliff_sensor_back_left_sensor" type="ray">
      <update_rate>50</update_rate>
      <visualize>true</visualize>
      <ray>
        <range>
          <min>0.02</min>
          <max>0.2</max>
          <resolution>1</resolution>
        </range>
        <scan>
          <horizontal>
            <samples>3</samples>
            <min_angle>-0.01</min_angle>
            <max_angle>0.01</max_angle>
          </horizontal>

        </scan>
      </ray>
      <plugin filename="libgazebo_ros_cliff.so" name="cliff_sensor_back_left_plugin">
        <gaussianNoise>0.000</gaussianNoise>
        <threshold>0.06</threshold>
        <topicName>cliff</topicName>
        <frameName>cliff_sensor_back_left</frameName>
        <radiation>infrared</radiation>
        <fov>0</fov>
        <updateRate>0</updateRate>
        <robotNamespace>/myRobot</robotNamespace>
      </plugin>
    </sensor>
  </gazebo>
  <joint name="cliff_sensor_center_joint" type="fixed">
    <axis xyz="0 0 1"/>
    <origin rpy="0 1.57079632679 0" xyz="0.1 0.0 0.0"/>
    <parent link="base_link"/>
    <child link="cliff_sensor_center_link"/>
  </joint>
  <link name="cliff_sensor_center_link">
    <collision>
      <origin rpy="0 0 0" xyz="0 0 0"/>
      <geometry>
        <box size="0.01 0.01 0.01"/>
      </geometry>
    </collision>
    <visual>
      <origin rpy="0 0 0" xyz="0 0 0"/>
      <geometry>
        <box size="0.01 0.01 0.01"/>
      </geometry>
      <material name="iRobot/Red"/>
    </visual>
    <inertial>
      <mass value="0.000000000000000001"/>
      <origin rpy="0 0 0" xyz="0 0 0"/>
      <inertia ixx="0.00000015" ixy="0" ixz="0" iyy="0.00000015" iyz="0" izz="0.00000015"/>
    </inertial>
  </link>
  <gazebo reference="cliff_sensor_center_link">
    <sensor name="cliff_sensor_center_sensor" type="ray">
      <update_rate>50</update_rate>
      <visualize>true</visualize>
      <ray>
        <range>
          <min>0.02</min>
          <max>0.2</max>
          <resolution>1</resolution>
        </range>
        <scan>
          <horizontal>
            <samples>3</samples>
            <min_angle>-0.01</min_angle>
            <max_angle>0.01</max_angle>
          </horizontal>

        </scan>
      </ray>
      <plugin filename="libgazebo_ros_cliff.so" name="cliff_sensor_center_plugin">
        <gaussianNoise>0.000</gaussianNoise>
        <threshold>0.06</threshold>
        <topicName>cliff</topicName>
        <frameName>cliff_sensor_center</frameName>
        <radiation>infrared</radiation>
        <fov>0</fov>
        <updateRate>0</updateRate>
        <robotNamespace>/myRobot</robotNamespace>
      </plugin>
    </sensor>
  </gazebo>
  <joint name="wheel_drop_left_sonar_joint" type="fixed">
    <axis xyz="0 0 1"/>
    <origin rpy="0 1.57079632679 0" xyz="0.0 0.1 0.0"/>
    <parent link="base_link"/>
    <child link="wheel_drop_left_sonar_link"/>
  </joint>
  <link name="wheel_drop_left_sonar_link">
    <collision>
      <origin rpy="0 0 0" xyz="0 0 0"/>
      <geometry>
        <box size="0.01 0.01 0.01"/>
      </geometry>
    </collision>
    <visual>
      <origin rpy="0 0 0" xyz="0 0 0"/>
      <geometry>
        <box size="0.01 0.01 0.01"/>
      </geometry>
      <material name="iRobot/Red"/>
    </visual>
    <inertial>
      <mass value="0.000000000000000001"/>
      <origin rpy="0 0 0" xyz="0 0 0"/>
      <inertia ixx="0.00000015" ixy="0" ixz="0" iyy="0.00000015" iyz="0" izz="0.00000015"/>
    </inertial>
  </link>
  <gazebo reference="wheel_drop_left_sonar_link">
    <sensor name="wheel_drop_left_sonar_sensor" type="ray">
      <update_rate>50</update_rate>
      <visualize>true</visualize>
      <ray>
        <range>
          <min>0.02</min>
          <max>0.2</max>
          <resolution>1</resolution>
        </range>
        <scan>
          <horizontal>
            <samples>3</samples>
            <min_angle>-0.01</min_angle>
            <max_angle>0.01</max_angle>
          </horizontal>
          <!--
                <vertical>
                  <samples>3</samples>
                  <min_angle>-0.0436</min_angle>
                  <max_angle>0.0436</max_angle>
                </vertical>
-->
        </scan>
      </ray>
      <plugin filename="libgazebo_ros_wheel_drop.so" name="wheel_drop_left_sonar_plugin">
        <gaussianNoise>0.000</gaussianNoise>
        <topicName>wheel_drop</topicName>
        <frameName>wheel_drop_left_sonar</frameName>
        <threshold>0.06</threshold>
        <radiation>infrared</radiation>
        <fov>0</fov>
        <updateRate>0</updateRate>
        <robotNamespace>/myRobot</robotNamespace>
      </plugin>
    </sensor>
  </gazebo>
  <joint name="wheel_drop_right_sonar_joint" type="fixed">
    <axis xyz="0 0 1"/>
    <origin rpy="0 1.57079632679 0" xyz="0.0 -0.1 0.0"/>
    <parent link="base_link"/>
    <child link="wheel_drop_right_sonar_link"/>
  </joint>
  <link name="wheel_drop_right_sonar_link">
    <collision>
      <origin rpy="0 0 0" xyz="0 0 0"/>
      <geometry>
        <box size="0.01 0.01 0.01"/>
      </geometry>
    </collision>
    <visual>
      <origin rpy="0 0 0" xyz="0 0 0"/>
      <geometry>
        <box size="0.01 0.01 0.01"/>
      </geometry>
      <material name="iRobot/Red"/>
    </visual>
    <inertial>
      <mass value="0.000000000000000001"/>
      <origin rpy="0 0 0" xyz="0 0 0"/>
      <inertia ixx="0.00000015" ixy="0" ixz="0" iyy="0.00000015" iyz="0" izz="0.00000015"/>
    </inertial>
  </link>
  <gazebo reference="wheel_drop_right_sonar_link">
    <sensor name="wheel_drop_right_sonar_sensor" type="ray">
      <update_rate>50</update_rate>
      <visualize>true</visualize>
      <ray>
        <range>
          <min>0.02</min>
          <max>0.2</max>
          <resolution>1</resolution>
        </range>
        <scan>
          <horizontal>
            <samples>3</samples>
            <min_angle>-0.01</min_angle>
            <max_angle>0.01</max_angle>
          </horizontal>

        </scan>
      </ray>
      <plugin filename="libgazebo_ros_wheel_drop.so" name="wheel_drop_right_sonar_plugin">
        <gaussianNoise>0.000</gaussianNoise>
        <topicName>wheel_drop</topicName>
        <frameName>wheel_drop_right_sonar</frameName>
        <threshold>0.06</threshold>
        <radiation>infrared</radiation>
        <fov>0</fov>
        <updateRate>0</updateRate>
        <robotNamespace>/myRobot</robotNamespace>
      </plugin>
    </sensor>
  </gazebo>
  <joint name="buttom_brush_joint" type="continuous">
    <!--<origin rpy="0 0 0" xyz="0.1 -0.14 0"/>-->
    <origin rpy="0 0 0" xyz="-0.15 0.0 -0.01"/>
    <axis xyz="0 1 0"/>
    <limit effort="100" velocity="100"/>
    <joint_properties damping="0.0" friction="0.0"/>
    <!--<parent link="chassis"/>-->
    <parent link="chassis"/>
    <child link="buttom_brush_link"/>
  </joint>

  <link name="buttom_brush_link">
    <inertial>
      <origin rpy="-1.57079632679 0 0" xyz="0 0.01 0"/>
      <mass value="0.001"/>
      <inertia ixx="0.0001" ixy="0.0" ixz="0.0" iyy="0.0001" iyz="0.0" izz="0.0001"/>
    </inertial>
    <visual>
      <origin rpy="-1.57079632679 0 0" xyz="0 0 0"/>
      <geometry>
        <box size="0.02 0.02 0.06"/>
      </geometry>
      <material name="myRobot/Red"/>
    </visual>
    <collision>
      <origin rpy="-1.57079632679 0 0" xyz="0 0 0"/>
      <geometry>
        <box size="0.01 0.01 0.01"/>
      </geometry>
    </collision>
  </link>
  <!--side brush left-->

  <!-- sec add end -->
  <gazebo reference="base_link">
    </gazebo>
  <gazebo reference="ground">
    </gazebo>
  <gazebo reference="sphere1">
    <gravity>true</gravity>
    <material>Gazebo/Grey</material>
    <mu1>0</mu1>
    <mu2>0</mu2>
    <kp>10000000</kp>
    <kd>1</kd>
    <fdir1>1 0 0</fdir1>
    <minDepth>0.0001</minDepth>
    <maxContacts>1</maxContacts>
  </gazebo>
  <gazebo reference="sphere2">
    <gravity>true</gravity>
    <material>Gazebo/Grey</material>
    <mu1>0</mu1>
    <mu2>0</mu2>
    <kp>10000000</kp>
    <kd>1</kd>
    <fdir1>1 0 0</fdir1>
    <minDepth>0.0001</minDepth>
    <maxContacts>1</maxContacts>
  </gazebo>
  <gazebo reference="chassis">
    <gravity>true</gravity>
    <!-- sec del start -->
    <!--
      <material>Gazebo/Yellow</material>
-->
    <!-- sec del end -->
  </gazebo>
  <gazebo>
    <static>false</static>
    <plugin filename="libgazebo_ros_diff_drive.so" name="differential_drive_controller">
      <rosDebugLevel>ERROR</rosDebugLevel>
      <publishWheelTF>false</publishWheelTF>
      <publishWheelJointState>true</publishWheelJointState>
      <alwaysOn>true</alwaysOn>
      <leftJoint>left_wheel_rot_joint</leftJoint>
      <rightJoint>right_wheel_rot_joint</rightJoint>
      <wheelSeparation>0.296</wheelSeparation>
      <wheelDiameter>0.06</wheelDiameter>
      <torque>20</torque>
      <wheelAcceleration>1.8</wheelAcceleration>
      <commandTopic>cmd_vel</commandTopic>
      <odometryTopic>odom</odometryTopic>
      <odometryFrame>odom</odometryFrame>
      <odometrySource>world</odometrySource>
      <robotBaseFrame>base_link</robotBaseFrame>
      <updateRate>30</updateRate>
      <!-- sec add start -->
      <legacyMode>false</legacyMode>
      <!-- default value -->
      <publishTf>1</publishTf>
      <!-- default value -->
      <wheelTorque>5</wheelTorque>
      <!-- default value -->
      <robotNamespace>/myRobot</robotNamespace>
      <!-- sec add end -->
    </plugin>
    <plugin filename="libgazebo_ros_joint_state_publisher.so" name="joint_state_publisher">
      <jointName>left_wheel_rot_joint, right_wheel_rot_joint</jointName>
      <updateRate>10.0</updateRate>
      <alwaysOn>true</alwaysOn>
      <robotNamespace>/myRobot</robotNamespace>
    </plugin>
    <plugin filename="libgazebo_ros_imu.so" name="imu_plugin">
      <bodyName>base_link</bodyName>
      <updateRate>100.0</updateRate>
      <topicName>imu_data</topicName>
      <serviceName>imu_service</serviceName>
      <gaussianNoise>0</gaussianNoise>
      <xyzOffset>0 0 0</xyzOffset>
      <rpyOffset>0 0 0</rpyOffset>
      <robotNamespace>/myRobot</robotNamespace>
    </plugin>
  </gazebo>
  <!-- sec add start -->
  <gazebo>

    <plugin filename="libgazebo_ros_dust_full.so" name="dust_full_controller">
      <robotNamespace>/myRobot</robotNamespace>
      <updateRate>0.01</updateRate>
      <dustFullTime>15.0</dustFullTime>
    </plugin>
    <plugin filename="libgazebo_ros_dust_box_sw.so" name="dust_box_controller">
      <robotNamespace>/myRobot</robotNamespace>
      <updateRate>0.5</updateRate>
    </plugin>

    <plugin filename="libgazebo_ros_slip_holl_sensor.so" name="slip">
      <robotNamespace>/myRobot</robotNamespace>
      <rosDebugLevel>WARN</rosDebugLevel>
      <updateRate>1.0</updateRate>
      <alwaysOn>true</alwaysOn>
      <!--
      <FrontLeftJoint>left_wheel_rot_joint</FrontLeftJoint>
      <FrontRightJoint>right_wheel_rot_joint</FrontRightJoint> -->
      <RearJoint>sphere_joint2</RearJoint>
    </plugin>
    
    <plugin filename="libgazebo_ros_buttom_brush.so" name="buttom_brush_controller">
      <robotNamespace>/myRobot</robotNamespace>
      <rosDebugLevel>WARN</rosDebugLevel>
      <brushJoint1>buttom_brush_joint</brushJoint1>
      <brushJoint2>left_brush_joint</brushJoint2>
      <brushJoint3>right_brush_joint</brushJoint3>
      <commandTopic>brushes_cmd</commandTopic>
      <outTopic>brushes</outTopic>
      <vacuumTopic>brushes_vacuum</vacuumTopic>
      <updateRate>0.1</updateRate>
    </plugin>
    
    <plugin filename="libgazebo_ros_vacuum_gripper.so" name="vacuum">
      <robotNamespace>/myRobot</robotNamespace>
      <FarSensorRadius>0.3</FarSensorRadius>
      <NearSensorRadius>0.2</NearSensorRadius>
      <FarVacuumCoefficient>0.5</FarVacuumCoefficient>
      <NearVacuumCoefficient>5</NearVacuumCoefficient>
      <MassThreshold>0.4</MassThreshold>
      <updateRate>0.1</updateRate>
      <bodyName>base_link</bodyName>
      <topicName>vacuum</topicName>
      <topicNameIn>cmd_brushes</topicNameIn>
      <topicNameOut>brushes_vacuum</topicNameOut>
      <topicNameDirtDetect>dirt_detect</topicNameDirtDetect>
      <topicNameDeleteModel>delete_model</topicNameDeleteModel>
      <vacuumForce>0.02</vacuumForce>
    </plugin>
    
    <plugin filename="libgazebo_ros_visual_pub.so" name="visual_pub">
      <robotNamespace>/myRobot</robotNamespace>
      <rosDebugLevel>WARN</rosDebugLevel>
      <topicName>mybot_pos</topicName>
      <updateRate>5</updateRate>
    </plugin>
  </gazebo>
  <!-- sec add end -->
</robot>
